Workbook

Sheet Assignment Audit
A1: Sem | B1: Wk | C1: Due | D1: Code | E1: Assignment | F1: Unit | G1: Type | H1: Aligned outcome(s) | I1: Change for 26-27
A2: S1 | B2: 1 | C2: 9/4 | D2: +NEW | E2: Who am I? | F2: U0 Identity & Community | G2: Classwork
A3: S1 | B3: 2 | C3: 9/11 | D3: +NEW | E3: Statue of Liberty Redesign | F3: U0 Identity & Community | G3: Classwork | H3: C1.6-8.3 | I3: Modified lesson
A4: S1 | B4: 3 | C4: 9/16 | D4: +NEW | E4: Three Colonial Regions | F4: U1 The 13 Colonies | G4: Classwork | H4: G1.6-8.5
A5: S1 | B5: 3 | C5: 9/19 | D5: P1 | E5: Weeks 1-3 Professionalism | F5: U1 The 13 Colonies | G5: Professionalism
A6: S1 | B6: 4 | C6: 9/25 | D6: +NEW | E6: Indigenous Perspectives | F6: U1 The 13 Colonies | G6: Classwork | H6: H3.6-8.4
A7: S1 | B7: 4 | C7: 9/24 | D7: +NEW | E7: The Mayflower Compact | F7: U1 The 13 Colonies | G7: Classwork | H7: C1.6-8.3 | I7: Modified lesson
A8: S1 | B8: 7 | C8: 10/15 | D8: +NEW | E8: Causes of Unrest | F8: U3 Revolutionary Voices | G8: Classwork | H8: H3.6-8.5, SSS1.6-8.1 | I8: Re-tagged (no lesson change)
A9: S1 | B9: 7 | D9: F-new | E9: Triangle Trade Economics Debrief | F9: U2 Triangle Trade | G9: Formative | H9: E1.6-8.3, E2.6-8.5, E2.6-8.6, E4.6-8.5 | I9: NEW (make graded)
A10: S1 | B10: 9 | C10: 10/30 | D10: +NEW | E10: DOI - 1776 | F10: U3 Revolutionary Voices | G10: Classwork | H10: C1.6-8.3, H3.6-8.4
A11: S1 | B11: 10 | C11: 11/05 | D11: +NEW | E11: DOI Translation | F11: U3 Revolutionary Voices | G11: Classwork | H11: C1.6-8.3
A12: S1 | B12: 10 | C12: 11/03 | D12: +NEW | E12: Uncovering Loyalties | F12: U3 Revolutionary Voices | G12: Classwork | H12: H3.6-8.4
A13: S1 | B13: 11 | D13: +NEW | E13: Quiz 2 - Road to Independence & Declaration | F13: U3 Revolutionary Voices | G13: Quiz | H13: H1.6-8.6
A14: S1 | B14: 12 | C14: 11/24 | D14: +NEW | E14: EdPuzzle - AoC | F14: U3 Revolutionary Voices | G14: Classwork | H14: C2.6-8.3
A15: S1 | B15: 12 | C15: 11/17 | D15: +NEW | E15: Podcast Submission | F15: U3 Revolutionary Voices | G15: Classwork | H15: SSS4.6-8.1, SSS4.6-8.2, H2.6-8.5, SSS2.6-8.1 | I15: Re-tagged (no lesson change)
A16: S1 | B16: 12 | C16: 11/05 | D16: +NEW | E16: Script Submission | F16: U3 Revolutionary Voices | G16: Classwork | H16: SSS4.6-8.1, SSS2.6-8.2, SSS2.6-8.1 | I16: Re-tagged (no lesson change)
A17: S1 | B17: 14 | C17: 12/5 | D17: +NEW | E17: Constitution Scavenger Hunt | F17: U4 The Constitution | G17: Classwork | H17: C2.6-8.3, C1.6-8.3 | I17: Modified lesson
A18: S1 | B18: 15 | C18: 12/12 | D18: +NEW | E18: Bill of Rights (Future Fright) | F18: U4 The Constitution | G18: Classwork | H18: C1.6-8.3
A19: S1 | B19: 17 | C19: 1/8 | D19: +NEW | E19: STI: Greenville Treaty CER | F19: U4 The Constitution | G19: Classwork | H19: SSS1.6-8.2, SSS4.6-8.1, C3.6-8.5
A20: S1 | B20: 18 | D20: +NEW | E20: Quiz 3 - Constitution & Bill of Rights | F20: U4 The Constitution | G20: Quiz | H20: C1.6-8.3, C2.6-8.5
A21: S1 | B21: 19 | D21: +NEW | E21: Capstone Project Overview | F21: U5 S1 Capstone | G21: Project | H21: C1.6-8.4, H4.6-8.3, SSS4.6-8.1
A22: S2 | B22: 1 | C22: 1/29 | D22: F1 | E22: 6.1 - Who gets to be an American? | F22: U6 SCOTUS (Civics CBA) | G22: Formative | H22: C1.6-8.4, C4.6-8.4 | I22: Add WALT
A23: S2 | B23: 1 | C23: 01/19 | D23: S1 | E23: Capstone Project | F23: U6 SCOTUS (Civics CBA) | G23: Summative | H23: C1.6-8.4, H4.6-8.3, SSS4.6-8.1
A24: S2 | B24: 2 | D24: F2 | E24: 6.4 - SCOTUS Poster | F24: U6 SCOTUS (Civics CBA) | G24: Formative | H24: C2.6-8.5, C2.6-8.3 | I24: Modified lesson
A25: S2 | B25: 2 | C25: 2/6 | D25: F3 | E25: 6.5 - Supreme Dilemmas | F25: U6 SCOTUS (Civics CBA) | G25: Formative | H25: C2.6-8.5, C4.6-8.4, C2.6-8.4 | I25: Re-tagged (no lesson change)
A26: S2 | B26: 2 | D26: S2 | E26: SCOTUS Vocab Quiz | F26: U6 SCOTUS (Civics CBA) | G26: Summative | H26: C2.6-8.3
A27: S2 | B27: 3 | C27: 02/18 | D27: S3 | E27: Opening/Closing Statements | F27: U6 SCOTUS (Civics CBA) | G27: Summative | H27: SSS4.6-8.1, SSS4.6-8.2, SSS1.6-8.2
A28: S2 | B28: 5 | C28: 2/25 | D28: F5 | E28: Edpuzzle | Sonia Sotomayor | F28: U6 SCOTUS (Civics CBA) | G28: Formative | H28: C2.6-8.3
A29: S2 | B29: 5 | C29: 02/20 | D29: F4 | E29: SCOTUS Debate | F29: U6 SCOTUS (Civics CBA) | G29: Formative | H29: SSS3.6-8.1, C2.6-8.5, C4.6-8.4
A30: S2 | B30: 6 | C30: 3/6 | D30: F6 | E30: Federalist? Pre-assessment | F30: U7 Early Republic | G30: Formative | H30: C2.6-8.6
A31: S2 | B31: 6 | D31: S4 | E31: SCOTUS Unit Quiz | F31: U7 Early Republic | G31: Summative | H31: C2.6-8.5, C2.6-8.3
A32: S2 | B32: 7 | C32: 03/09 | D32: S5 | E32: What do you think? | F32: U7 Early Republic | G32: Summative | H32: SSS3.6-8.1, H4.6-8.3, C2.6-8.4, C2.6-8.6 | I32: Re-tagged (no lesson change)
A33: S2 | B33: 8 | C33: 3/18 | D33: F7 | E33: Lewis & Clark Journal | F33: U7 Early Republic | G33: Formative | H33: G1.6-8.6, H2.6-8.5, H3.6-8.4, G2.6-8.6 | I33: Modified lesson
A34: S2 | B34: 9 | D34: F8★ | E34: The Big Decisions Project | F34: U7 Early Republic | G34: Summative | H34: SSS3.6-8.1, E3.6-8.3, C3.6-8.5, E1.6-8.3, E4.6-8.6, SSS4.6-8.1, SSS2.6-8.1 | I34: NEW (make graded)
A35: S2 | B35: 10 | C35: 3/31 | D35: S6 | E35: Early Republic Quiz | F35: U7 Early Republic | G35: Summative | H35: H1.6-8.6, C3.6-8.5
A36: S2 | B36: 10 | C36: 03/30 | D36: EC1 | E36: Message to Jefferson | F36: U7 Early Republic | G36: Extra Credit | H36: C3.6-8.5, H2.6-8.5
A37: S2 | B37: 10 | C37: 3/31 | D37: EC2 | E37: War of 1812 | F37: U7 Early Republic | G37: Extra Credit | H37: C3.6-8.5, H2.6-8.7
A38: S2 | B38: 11 | C38: 4/14 | D38: F9 | E38: Westward Expansion Week 1 | F38: U8 Westward Expansion | G38: Formative | H38: H3.6-8.4, SSS1.6-8.1 | I38: Re-tagged (no lesson change)
A39: S2 | B39: 12 | C39: 4/20 | D39: S7 | E39: Jackson: Hero, Villain, Both? | F39: U8 Westward Expansion | G39: Summative | H39: H3.6-8.4, H3.6-8.5, SSS1.6-8.2
A40: S2 | B40: 13 | D40: F-new | E40: Territorial Expansion Maps | F40: U8 Westward Expansion | G40: Formative | H40: G1.6-8.6, G3.6-8.3, G2.6-8.6, G2.6-8.8 | I40: NEW (make graded)
...

Sheet Outcome Coverage
A1: Outcome | B1: Strand | C1: # assignments | D1: Coverage | E1: Standard text
A2: C1.6-8.3 | B2: Civics | C2: =COUNTIF('Assignment Audit'!H2:H55,"*"&A2&"*") -> 7 | D2: =IF(C2=0,"GAP",IF(C2=1,"THIN","covered")) -> covered | E2: Explain key ideals and principles outlined in the Declaration of Independence, including life, liberty, and the pursuit of happiness; the U.S. Constitution, including the rule of law, separation of powers, representative government, and popular sovereignty; and, the Bill of Rights, including due process and freedom of expression.
A3: C1.6-8.4 | B3: Civics | C3: =COUNTIF('Assignment Audit'!H2:H55,"*"&A3&"*") -> 6 | D3: =IF(C3=0,"GAP",IF(C3=1,"THIN","covered")) -> covered | E3: Evaluate efforts to reduce discrepancies between key ideals and reality in the United States.
A4: C2.6-8.3 | B4: Civics | C4: =COUNTIF('Assignment Audit'!H2:H55,"*"&A4&"*") -> 6 | D4: =IF(C4=0,"GAP",IF(C4=1,"THIN","covered")) -> covered | E4: Analyze the structure and powers of government at the national level.
A5: C2.6-8.4 | B5: Civics | C5: =COUNTIF('Assignment Audit'!H2:H55,"*"&A5&"*") -> 2 | D5: =IF(C5=0,"GAP",IF(C5=1,"THIN","covered")) -> covered | E5: Use knowledge of the function of government to analyze and address a political issue.
A6: C2.6-8.5 | B6: Civics | C6: =COUNTIF('Assignment Audit'!H2:H55,"*"&A6&"*") -> 5 | D6: =IF(C6=0,"GAP",IF(C6=1,"THIN","covered")) -> covered | E6: Evaluate the effectiveness of the system of checks and balances in the United States based on an event.
A7: C2.6-8.6 | B7: Civics | C7: =COUNTIF('Assignment Audit'!H2:H55,"*"&A7&"*") -> 2 | D7: =IF(C7=0,"GAP",IF(C7=1,"THIN","covered")) -> covered | E7: Demonstrate that the U.S. government includes concepts of both a democracy and a republic.
A8: C3.6-8.5 | B8: Civics | C8: =COUNTIF('Assignment Audit'!H2:H55,"*"&A8&"*") -> 5 | D8: =IF(C8=0,"GAP",IF(C8=1,"THIN","covered")) -> covered | E8: Identify early examples of foreign policy between the United States and other nations.
A9: C3.6-8.6 | B9: Civics | C9: =COUNTIF('Assignment Audit'!H2:H55,"*"&A9&"*") -> 2 | D9: =IF(C9=0,"GAP",IF(C9=1,"THIN","covered")) -> covered | E9: Analyze how the United States has interacted with other countries.
A10: C4.6-8.4 | B10: Civics | C10: =COUNTIF('Assignment Audit'!H2:H55,"*"&A10&"*") -> 4 | D10: =IF(C10=0,"GAP",IF(C10=1,"THIN","covered")) -> covered | E10: Analyze how a claim on an issue attempts to balance individual rights and the common good.
A11: C4.6-8.5 | B11: Civics | C11: =COUNTIF('Assignment Audit'!H2:H55,"*"&A11&"*") -> 2 | D11: =IF(C11=0,"GAP",IF(C11=1,"THIN","covered")) -> covered | E11: Employ strategies for civic involvement that address a national issue.
A12: E1.6-8.3 | B12: Economics | C12: =COUNTIF('Assignment Audit'!H2:H55,"*"&A12&"*") -> 2 | D12: =IF(C12=0,"GAP",IF(C12=1,"THIN","covered")) -> covered | E12: Analyze examples of how groups and individuals have considered profit and personal values in making economic choices in the past or present.
A13: E2.6-8.5 | B13: Economics | C13: =COUNTIF('Assignment Audit'!H2:H55,"*"&A13&"*") -> 3 | D13: =IF(C13=0,"GAP",IF(C13=1,"THIN","covered")) -> covered | E13: Analyze how the forces of supply and demand have affected the production, distribution, and consumption of goods, services, and resources in the United States in the past or present.
A14: E2.6-8.6 | B14: Economics | C14: =COUNTIF('Assignment Audit'!H2:H55,"*"&A14&"*") -> 2 | D14: =IF(C14=0,"GAP",IF(C14=1,"THIN","covered")) -> covered | E14: Analyze how the forces of supply and demand have affected international trade in the United States in the past or present.
A15: E3.6-8.3 | B15: Economics | C15: =COUNTIF('Assignment Audit'!H2:H55,"*"&A15&"*") -> 2 | D15: =IF(C15=0,"GAP",IF(C15=1,"THIN","covered")) -> covered | E15: Analyze the influence of the U.S. government’s taxation, creation of currency, and tariffs in the past or present.
A16: E4.6-8.5 | B16: Economics | C16: =COUNTIF('Assignment Audit'!H2:H55,"*"&A16&"*") -> 2 | D16: =IF(C16=0,"GAP",IF(C16=1,"THIN","covered")) -> covered | E16: Analyze the distribution of wealth and sustainability of resources in the United States.
A17: E4.6-8.6 | B17: Economics | C17: =COUNTIF('Assignment Audit'!H2:H55,"*"&A17&"*") -> 2 | D17: =IF(C17=0,"GAP",IF(C17=1,"THIN","covered")) -> covered | E17: Explain the costs and benefits of trade policies to individuals, businesses, and society in the United States.
A18: G1.6-8.5 | B18: Geography | C18: =COUNTIF('Assignment Audit'!H2:H55,"*"&A18&"*") -> 2 | D18: =IF(C18=0,"GAP",IF(C18=1,"THIN","covered")) -> covered | E18: Explain and analyze physical and cultural characteristics of places and regions in the United States.
A19: G1.6-8.6 | B19: Geography | C19: =COUNTIF('Assignment Audit'!H2:H55,"*"&A19&"*") -> 2 | D19: =IF(C19=0,"GAP",IF(C19=1,"THIN","covered")) -> covered | E19: Use maps, satellite images, photographs, and other representations to explain relationships between the locations of places and regions and their political, cultural, and economic dynamics.
A20: G2.6-8.6 | B20: Geography | C20: =COUNTIF('Assignment Audit'!H2:H55,"*"&A20&"*") -> 2 | D20: =IF(C20=0,"GAP",IF(C20=1,"THIN","covered")) -> covered | E20: Analyze how the environment has affected people and how people have affected the environment in the United States in the past or present.
A21: G2.6-8.7 | B21: Geography | C21: =COUNTIF('Assignment Audit'!H2:H55,"*"&A21&"*") -> 3 | D21: =IF(C21=0,"GAP",IF(C21=1,"THIN","covered")) -> covered | E21: Explain cultural diffusion in the United States from the past or in the present.
A22: G2.6-8.8 | B22: Geography | C22: =COUNTIF('Assignment Audit'!H2:H55,"*"&A22&"*") -> 3 | D22: =IF(C22=0,"GAP",IF(C22=1,"THIN","covered")) -> covered | E22: Explain and analyze migration as a catalyst for the growth of the United States in the past or present.
A23: G3.6-8.3 | B23: Geography | C23: =COUNTIF('Assignment Audit'!H2:H55,"*"&A23&"*") -> 2 | D23: =IF(C23=0,"GAP",IF(C23=1,"THIN","covered")) -> covered | E23: Explain how learning about the geography of the United States helps us understand global issues such as diversity, trade, and sustainability.
A24: H1.6-8.6 | B24: History | C24: =COUNTIF('Assignment Audit'!H2:H55,"*"&A24&"*") -> 6 | D24: =IF(C24=0,"GAP",IF(C24=1,"THIN","covered")) -> covered | E24: Explain how themes and developments help to define eras in United States history from 1763 to 1877, including: Fighting for independence (1763-1783); Establishing the new nation (1781-1815); Slavery, expansion, removal, and reform (1801-1850); Civil War and Reconstruction (1850-1877)
A25: H2.6-8.5 | B25: History | C25: =COUNTIF('Assignment Audit'!H2:H55,"*"&A25&"*") -> 4 | D25: =IF(C25=0,"GAP",IF(C25=1,"THIN","covered")) -> covered | E25: Explain and analyze how individuals and movements have shaped United States history (1763-1877).
A26: H2.6-8.6 | B26: History | C26: =COUNTIF('Assignment Audit'!H2:H55,"*"&A26&"*") -> 2 | D26: =IF(C26=0,"GAP",IF(C26=1,"THIN","covered")) -> covered | E26: Explain and analyze how cultures and cultural and ethnic groups have contributed to United States history (1763-1877).
A27: H2.6-8.7 | B27: History | C27: =COUNTIF('Assignment Audit'!H2:H55,"*"&A27&"*") -> 2 | D27: =IF(C27=0,"GAP",IF(C27=1,"THIN","covered")) -> covered | E27: Explain and analyze how technology and ideas have impacted United States history (1763-1877).
A28: H3.6-8.4 | B28: History | C28: =COUNTIF('Assignment Audit'!H2:H55,"*"&A28&"*") -> 11 | D28: =IF(C28=0,"GAP",IF(C28=1,"THIN","covered")) -> covered | E28: Analyze and interpret historical materials from a variety of perspectives in United States history (1763-1877).
A29: H3.6-8.5 | B29: History | C29: =COUNTIF('Assignment Audit'!H2:H55,"*"&A29&"*") -> 4 | D29: =IF(C29=0,"GAP",IF(C29=1,"THIN","covered")) -> covered | E29: Analyze multiple causal factors to create positions on major events in United States history (1763-1877).
A30: H4.6-8.3 | B30: History | C30: =COUNTIF('Assignment Audit'!H2:H55,"*"&A30&"*") -> 5 | D30: =IF(C30=0,"GAP",IF(C30=1,"THIN","covered")) -> covered | E30: Analyze how a historical event in United States history helps us to understand contemporary issues and events.
A31: SSS1.6-8.1 | B31: Skills | C31: =COUNTIF('Assignment Audit'!H2:H55,"*"&A31&"*") -> 3 | D31: =IF(C31=0,"GAP",IF(C31=1,"THIN","covered")) -> covered | E31: Analyze positions and evidence supporting an issue or an event.
A32: SSS1.6-8.2 | B32: Skills | C32: =COUNTIF('Assignment Audit'!H2:H55,"*"&A32&"*") -> 3 | D32: =IF(C32=0,"GAP",IF(C32=1,"THIN","covered")) -> covered | E32: Evaluate the logic of reasons for a position on an issue or event.
A33: SSS2.6-8.1 | B33: Skills | C33: =COUNTIF('Assignment Audit'!H2:H55,"*"&A33&"*") -> 4 | D33: =IF(C33=0,"GAP",IF(C33=1,"THIN","covered")) -> covered | E33: Create and use research questions to guide inquiry on an issue or event.
A34: SSS2.6-8.2 | B34: Skills | C34: =COUNTIF('Assignment Audit'!H2:H55,"*"&A34&"*") -> 2 | D34: =IF(C34=0,"GAP",IF(C34=1,"THIN","covered")) -> covered | E34: Evaluate the breadth, reliability, and credibility of primary and secondary sources to determine the need for new or additional information when researching an issue or event.
A35: SSS3.6-8.1 | B35: Skills | C35: =COUNTIF('Assignment Audit'!H2:H55,"*"&A35&"*") -> 3 | D35: =IF(C35=0,"GAP",IF(C35=1,"THIN","covered")) -> covered | E35: Engage in discussion, analyzing multiple viewpoints on public issues.
A36: SSS4.6-8.1 | B36: Skills | C36: =COUNTIF('Assignment Audit'!H2:H55,"*"&A36&"*") -> 8 | D36: =IF(C36=0,"GAP",IF(C36=1,"THIN","covered")) -> covered | E36: Analyze multiple factors, make generalizations, and interpret sources to formulate a thesis in a paper or presentation, while observing rules related to plagiarism and copyright.
A37: SSS4.6-8.2 | B37: Skills | C37: =COUNTIF('Assignment Audit'!H2:H55,"*"&A37&"*") -> 2 | D37: =IF(C37=0,"GAP",IF(C37=1,"THIN","covered")) -> covered | E37: Use appropriate format to cite sources within an essay, presentation, and reference page.
